Workbook

Sheet Summary
A1: Slack Tide source tracker
A2: Compiled 2026-10-25 from docs/SOURCES.md and a live probe of 104 sites. Yellow cells on the Sources sheet are yours to edit; the rest is what the probe found.
A4: By action | D4: By status
A5: Add now | B5: =COUNTIF(Sources!$K$2:$K$119,A5) | D5: In use | E5: =COUNTIF(Sources!$E$2:$E$119,D5)
A6: Enable | B6: =COUNTIF(Sources!$K$2:$K$119,A6) | D6: Check | E6: =COUNTIF(Sources!$E$2:$E$119,D6)
A7: Build connector | B7: =COUNTIF(Sources!$K$2:$K$119,A7) | D7: Disabled | E7: =COUNTIF(Sources!$E$2:$E$119,D7)
A8: Write selectors | B8: =COUNTIF(Sources!$K$2:$K$119,A8) | D8: Candidate | E8: =COUNTIF(Sources!$E$2:$E$119,D8)
A9: Email for feed address | B9: =COUNTIF(Sources!$K$2:$K$119,A9) | D9: Declined | E9: =COUNTIF(Sources!$E$2:$E$119,D9)
A10: Ask for export | B10: =COUNTIF(Sources!$K$2:$K$119,A10)
A11: Offer the form | B11: =COUNTIF(Sources!$K$2:$K$119,A11)
A12: Confirm domain | B12: =COUNTIF(Sources!$K$2:$K$119,A12) | D12: By wave
A13: Retry probe | B13: =COUNTIF(Sources!$K$2:$K$119,A13) | D13: Wave 1 | E13: =COUNTIF(Sources!$J$2:$J$119,"1")
A14: Keep as check | B14: =COUNTIF(Sources!$K$2:$K$119,A14) | D14: Wave 2 | E14: =COUNTIF(Sources!$J$2:$J$119,"2")
A15: Declined | B15: =COUNTIF(Sources!$K$2:$K$119,A15) | D15: Wave 3 | E15: =COUNTIF(Sources!$J$2:$J$119,"3")
A16: Done | B16: =COUNTIF(Sources!$K$2:$K$119,A16) | D16: Wave 4 | E16: =COUNTIF(Sources!$J$2:$J$119,"4")
A17: Total | B17: =SUM(B5:B16)
A20: By town, live on site
A21: Town | B21: Live | C21: Candidates
A22: New Bedford | B22: =COUNTIFS(Sources!$A$2:$A$119,A22,Sources!$Q$2:$Q$119,"Yes") | C22: =COUNTIFS(Sources!$A$2:$A$119,A22,Sources!$E$2:$E$119,"Candidate")
A23: Fall River | B23: =COUNTIFS(Sources!$A$2:$A$119,A23,Sources!$Q$2:$Q$119,"Yes") | C23: =COUNTIFS(Sources!$A$2:$A$119,A23,Sources!$E$2:$E$119,"Candidate")
A24: Dartmouth | B24: =COUNTIFS(Sources!$A$2:$A$119,A24,Sources!$Q$2:$Q$119,"Yes") | C24: =COUNTIFS(Sources!$A$2:$A$119,A24,Sources!$E$2:$E$119,"Candidate")
A25: Fairhaven | B25: =COUNTIFS(Sources!$A$2:$A$119,A25,Sources!$Q$2:$Q$119,"Yes") | C25: =COUNTIFS(Sources!$A$2:$A$119,A25,Sources!$E$2:$E$119,"Candidate")
A26: Acushnet | B26: =COUNTIFS(Sources!$A$2:$A$119,A26,Sources!$Q$2:$Q$119,"Yes") | C26: =COUNTIFS(Sources!$A$2:$A$119,A26,Sources!$E$2:$E$119,"Candidate")
A27: Westport | B27: =COUNTIFS(Sources!$A$2:$A$119,A27,Sources!$Q$2:$Q$119,"Yes") | C27: =COUNTIFS(Sources!$A$2:$A$119,A27,Sources!$E$2:$E$119,"Candidate")
A28: Somerset | B28: =COUNTIFS(Sources!$A$2:$A$119,A28,Sources!$Q$2:$Q$119,"Yes") | C28: =COUNTIFS(Sources!$A$2:$A$119,A28,Sources!$E$2:$E$119,"Candidate")
A29: Swansea | B29: =COUNTIFS(Sources!$A$2:$A$119,A29,Sources!$Q$2:$Q$119,"Yes") | C29: =COUNTIFS(Sources!$A$2:$A$119,A29,Sources!$E$2:$E$119,"Candidate")
A30: Freetown | B30: =COUNTIFS(Sources!$A$2:$A$119,A30,Sources!$Q$2:$Q$119,"Yes") | C30: =COUNTIFS(Sources!$A$2:$A$119,A30,Sources!$E$2:$E$119,"Candidate")
A31: Mattapoisett | B31: =COUNTIFS(Sources!$A$2:$A$119,A31,Sources!$Q$2:$Q$119,"Yes") | C31: =COUNTIFS(Sources!$A$2:$A$119,A31,Sources!$E$2:$E$119,"Candidate")
A32: Marion | B32: =COUNTIFS(Sources!$A$2:$A$119,A32,Sources!$Q$2:$Q$119,"Yes") | C32: =COUNTIFS(Sources!$A$2:$A$119,A32,Sources!$E$2:$E$119,"Candidate")
A33: Rochester | B33: =COUNTIFS(Sources!$A$2:$A$119,A33,Sources!$Q$2:$Q$119,"Yes") | C33: =COUNTIFS(Sources!$A$2:$A$119,A33,Sources!$E$2:$E$119,"Candidate")
... A37: Regional | B37: =COUNTIFS(Sources!$A$2:$A$119,A37,Sources!$Q$2:$Q$119,"Yes") | C37: =COUNTIFS(Sources!$A$2:$A$119,A37,Sources!$E$2:$E$119,"Candidate")
A40: Legend
A41: Status: In use (published), Check (read for the coverage report, never published), Disabled (registry entry switched off), Candidate, Declined.
A42: Route: the integration we would use; see docs/SOURCES.md section 1 for what each costs.
A43: Action: the next thing to do for this source. Pick from the list; set Done when it is live or finished.
A44: Wave: the outreach wave from docs/SOURCES.md section 5 (1 = feeds in hand, 2 = build and read, 3 = one-email asks, 4 = relationships).
A45: Contacted on, Response, Live on site: fill in as outreach happens. Live on site means a registry entry is enabled and publishing.

Sheet Sources
A1: Town | B1: Organisation | C1: Domain | D1: Kind | E1: Status | F1: Platform found | G1: Feeds found | H1: Route | I1: Priority | J1: Wave | K1: Action | L1: Owner | M1: Contact name | N1: Contact email | O1: Contacted on | P1: Response | Q1: Live on site | R1: Notes
A2: New Bedford | B2: The Zeiterion | C2: zeiterion.org | D2: venue | E2: In use | F2: Webflow | G2: {} | H2: HTML listing | I2: High | K2: Done | P2: Not contacted | Q2: Yes | R2: Webflow listing; added 25 Oct
A3: Westport | B3: Buzzards Bay Brewing | C3: buzzardsbrew.com | D3: venue | E3: In use | F3: WordPress, Tribe | G3: {"tribe": "yes"} | H3: Tribe REST | I3: Medium | K3: Done | P3: Not contacted | Q3: Yes | R3: PHP warnings before JSON; 500 on 25 Oct
A4: Somerset | B4: Town of Somerset | C4: townofsomerset.org | D4: town | E4: In use | F4: CivicPlus | G4: {"civicplus-ical": "cats 14, 23"} | H4: CivicPlus iCal | I4: High | K4: Done | P4: Not contacted | Q4: Yes | R4: Cats 14 and 23
A5: Dartmouth | B5: Dartmouth Natural Resources Trust | C5: dnrt.org | D5: nature | E5: In use | F5: WordPress, Tribe | G5: {"tribe": "yes", "tribe-ical": "yes"} | H5: Tribe REST | I5: High | K5: Done | P5: Not contacted | Q5: Yes
A6: Dartmouth | B6: Town of Dartmouth | C6: dartmouthma.gov | D6: town | E6: In use | F6: CivicPlus | G6: {"civicplus-ical": "cats 14, 24"} | H6: CivicPlus iCal | I6: High | K6: Done | P6: Not contacted | Q6: Yes | R6: Cats 14 and 24
A7: Tiverton | B7: Town of Tiverton | C7: tiverton.ri.gov | D7: town | E7: In use | F7: CivicPlus | G7: {"civicplus-ical": "cats 14, 24"} | H7: CivicPlus iCal | I7: High | K7: Done | P7: Not contacted | Q7: Yes | R7: Cats 14 and 24; venues missing on most rows (issue 10)
A8: Little Compton | B8: Brownell Library | C8: brownell-libraryri.org | D8: library | E8: In use | F8: WordPress, Tribe | G8: {"tribe": "yes"} | H8: Tribe REST | I8: High | K8: Done | P8: Not contacted | Q8: Yes | R8: Feed sends no venue; registry default fills it
A9: Fall River | B9: Viva Fall River | C9: vivafallriver.com | D9: aggregator | E9: Check | F9: Site Kit by Google 1.188.0 wordpress, tribe-plugin, squarespace, ics-link | G9: {"tribe": 1925, "rss": 10} | H9: Check source | I9: High | K9: Keep as check | P9: Not contacted | Q9: No | R9: Aggregator; check role since 25 Oct (decision 10)
A10: Regional | B10: Explore New Bedford | C10: explorenewbedford.org | D10: aggregator | E10: Check | F10: WordPress 7.1.3 wordpress, tribe-plugin, mailchimp, ics-link | G10: {"tribe": 923, "tribe-ical": 30, "rss": 10} | H10: Check source | I10: High | K10: Keep as check | P10: Not contacted | Q10: No | R10: Aggregator; 923 future events
A11: New Bedford | B11: New Bedford Light | C11: newbedfordlight.org | D11: media | E11: Disabled | F11: (home 429) | G11: {"rss": 10} | H11: None | I11: Low | K11: Declined | P11: Not contacted | Q11: No | R11: Articles, not events; later extraction (issue 14)
A12: Mattapoisett | B12: Mattapoisett Land Trust | C12: mattlandtrust.org | D12: nature | E12: Disabled | F12: WordPress 6.8.11 wordpress, mailchimp, ics-link | G12: {"tribe": 2, "rss": 0} | H12: Tribe REST | I12: High | J12: 1 | K12: Enable | P12: Not contacted | Q12: No | R12: Probe confirmed 2 events
A13: Little Compton | B13: Little Compton Historical Society | C13: littlecompton.org | D13: history | E13: Disabled | F13: wordpress, tribe-plugin, mailchimp, ics-link, json-ld-event | G13: {} | H13: Tribe REST | I13: High | J13: 1 | K13: Enable | P13: Not contacted | Q13: No | R13: Probe rate-limited (429); test by hand
A14: Regional | B14: Buzzards Bay Coalition | C14: savebuzzardsbay.org | D14: nature | E14: Disabled | F14: SEOmatic craft | G14: {} | H14: Ticketing (ask) | I14: High | J14: 3 | K14: Ask for export | P14: Not contacted | Q14: No | R14: Bay Adventures dates in FareHarbor (issue 19)
A15: any | B15: Submissions (the /add/ form) | D15: form | E15: Disabled | F15: Google Form and Sheet | G15: {} | H15: Submission form | I15: High | J15: 1 | K15: Build connector | P15: Not contacted | Q15: No | R15: Configure the Google Form and sheet (issue 18)
A16: Fall River | B16: Canned Heat Craft Beer Co | C16: cannedheatbeer.com | D16: venue | E16: Candidate | F16: (home SSLError) | G16: {} | H16: Submission form | I16: High | J16: 4 | K16: Confirm domain | P16: Not contacted | Q16: No | R16: 9 series missed; certificate error on probe
A17: Fall River | B17: Children's Museum of Greater Fall River | C17: cmgfr.org | D17: museum | E17: Candidate | F17: squarespace | G17: {"squarespace-rss": 28} | H17: Squarespace JSON | I17: High | J17: 1 | K17: Build connector | P17: Not contacted | Q17: No | R17: /events?format=json answers with 8 dated items
A18: Fall River | B18: Fall River Public Library | C18: fallriverlibrary.org | D18: library | E18: Candidate | F18: WordPress 7.1.3 wordpress, whofi | G18: {"rss": 0} | H18: WhoFi | I18: High | J18: 2 | K18: Build connector | P18: Not contacted | Q18: No | R18: fallriver-ma.whofi.com; 14 series missed
A19: Fall River | B19: Narrows Center for the Arts | C19: narrowscenter.org | D19: venue | E19: Candidate | F19: wordpress | G19: {"rss": 10} | H19: HTML listing | I19: High | J19: 2 | K19: Write selectors | P19: Not contacted | Q19: No | R19: 19 series missed; tickets on ShoWare
A20: Fall River | B20: Battleship Cove | C20: battleshipcove.org | D20: museum | E20: Candidate | F20: Wix.com Website Builder wix | G20: {} | H20: Wix (ask) | I20: Medium | J20: 4 | K20: Email for feed address | P20: Not contacted | Q20: No | R20: Wix events viewer; 11 titles in page
A21: Fall River | B21: City of Fall River | C21: fallriverma.org | D21: town | E21: Candidate | F21: (home 403) | G21: {} | H21: CivicPlus iCal | I21: Medium | J21: 3 | K21: Email for feed address | P21: Not contacted | Q21: No | R21: Blocks the probe (403); confirm platform in a browser
A22: Fall River | B22: Fall River Historical Society | C22: fallriverhistorical.org | D22: history | E22: Candidate | F22: WordPress 7.1.3 wordpress | G22: {"rss": 0} | H22: HTML listing | I22: Medium | J22: 2 | K22: Write selectors | P22: Not contacted | Q22: No | R22: WordPress /events/
A23: Fall River | B23: Greater Fall River Re-CREATION | C23: re-creation.org | D23: recreation | E23: Candidate | G23: {} | H23: Submission form | I23: Medium | J23: 4 | K23: Offer the form | P23: Not contacted | Q23: No | R23: No platform detected
A24: Fall River | B24: SoCo Art Labs | C24: socoartlabs.com | D24: arts | E24: Candidate | F24: WordPress 7.1.3 wordpress, tribe-plugin, eventbrite, ics-link | G24: {"tribe": 0, "rss": 0} | H24: Eventbrite | I24: Medium | J24: 3 | K24: Email for feed address | P24: Not contacted | Q24: No | R24: Tribe installed but empty; uses Eventbrite
A25: Fall River | B25: Bristol Community College | C25: bristolcc.edu | D25: college | E25: Candidate | G25: {} | H25: HTML listing | I25: Low | J25: 2 | K25: Write selectors | P25: Not contacted | Q25: No | R25: Static upcoming events page
A26: Fall River | B26: Fall River Little Theatre | C26: fallriverlittletheatre.org | D26: theatre | E26: Candidate | F26: (home ConnectionError) | G26: {} | H26: None | I26: Low | J26: 4 | K26: Confirm domain | P26: Not contacted | Q26: No | R26: Unreachable
A27: Fall River | B27: Fall River Reporter | C27: fallriverreporter.com | D27: media | E27: Candidate | F27: WordPress 7.1.3 wordpress | G27: {"rss": 10} | H27: None | I27: Low | K27: Declined | P27: Not contacted | Q27: No | R27: Articles (RSS); later extraction
A28: Fall River | B28: Lafayette-Durfee House | C28: lafayettedurfeehouse.org | D28: history | E28: Candidate | F28: (home SSLError) | G28: {} | H28: None | I28: Low | J28: 4 | K28: Confirm domain | P28: Not contacted | Q28: No | R28: Certificate error
A29: Fall River | B29: Lizzie Borden House | C29: lizzie-borden.com | D29: attraction | E29: Candidate | F29: (home 403) | G29: {} | H29: None | I29: Low | J29: 4 | K29: Email for feed address | P29: Not contacted | Q29: No | R29: Blocks the probe (403)
A30: Fall River | B30: Marine Museum at Fall River | C30: marinemuseumfr.org | D30: museum | E30: Candidate | F30: (home SSLError) | G30: {} | H30: None | I30: Low | J30: 4 | K30: Confirm domain | P30: Not contacted | Q30: No | R30: Certificate error
A31: Fall River | B31: The Tipsy Toboggan | C31: thetipsytoboggan.com | D31: venue | E31: Candidate | F31: Wix.com Website Builder wix | G31: {} | H31: Submission form | I31: Low | J31: 4 | K31: Offer the form | P31: Not contacted | Q31: No | R31: Wix
A32: New Bedford | B32: Hatch Street Studios | C32: hatchstreetstudios.com | D32: arts | E32: Candidate | F32: squarespace | G32: {"squarespace-rss": 25} | H32: Squarespace JSON | I32: High | J32: 1 | K32: Build connector | P32: Not contacted | Q32: No | R32: /events?format=json answers with 5 dated items
A33: New Bedford | B33: New Bedford Art Museum | C33: newbedfordart.org | D33: museum | E33: Candidate | F33: WordPress 7.0.7 wordpress | G33: {"rss": 0} | H33: HTML listing | I33: High | J33: 2 | K33: Write selectors | P33: Not contacted | Q33: No | R33: /events/ with 17 headings; 8 missed
A34: New Bedford | B34: New Bedford Free Public Library | C34: nbfpl.org | D34: library | E34: Candidate | F34: Joomla! - Open Source Content Management google-calendar | G34: {} | H34: Plain iCal | I34: High | J34: 3 | K34: Email for feed address | P34: Not contacted | Q34: No | R34: Joomla with a Google Calendar embed; need calendar id
A35: New Bedford | B35: New Bedford Whaling Museum | C35: whalingmuseum.org | D35: museum | E35: Candidate | F35: WP Rocket 3.23.5.1 wordpress | G35: {"rss": 10} | H35: HTML listing | I35: High | J35: 2 | K35: Write selectors | P35: Not contacted | Q35: No | R35: program post type at /wp-json/wp/v2/program, no date field; 11 missed
A36: New Bedford | B36: AHA! New Bedford | C36: ahanewbedford.org | D36: arts | E36: Candidate | F36: All in One SEO (AIOSEO) 5.0.4 wordpress, tribe-plugin, ics-link | G36: {"tribe": 0, "rss": 10} | H36: Tribe REST | I36: Medium | J36: 3 | K36: Email for feed address | P36: Not contacted | Q36: No | R36: Plugin installed, three 2022 test events; ask them to use it
A37: New Bedford | B37: Buttonwood Park Zoo | C37: bpzoo.org | D37: attraction | E37: Candidate | F37: WordPress 7.1.3 wordpress | G37: {"rss": 10} | H37: HTML listing | I37: Medium | J37: 2 | K37: Retry probe | P37: Not contacted | Q37: No | R37: Find the events page
A38: New Bedford | B38: Co-Creative Center | C38: cocreativecenter.org | D38: arts | E38: Candidate | F38: (home ConnectionError) | G38: {} | H38: None | I38: Medium | J38: 4 | K38: Confirm domain | P38: Not contacted | Q38: No | R38: Unreachable
A39: New Bedford | B39: Gallery X | C39: galleryx.org | D39: arts | E39: Candidate | F39: WordPress 7.1.3 wordpress, mailchimp | G39: {"rss": 10} | H39: HTML listing | I39: Medium | J39: 2 | K39: Write selectors | P39: Not contacted | Q39: No | R39: EventPrime, 32 event links
... A44: New Bedford | B44: The Vault Performing Arts Center | C44: thevaultnb.com | D44: venue | E44: Candidate | F44: (home ConnectionError) | G44: {} | H44: None | I44: Medium | J44: 4 | K44: Confirm domain | P44: Not contacted | Q44: No | R44: Unreachable; open mic venue in the check
...

Sheet Lists
A1: Status | B1: Route | C1: Priority | D1: Wave | E1: Action | F1: Response | G1: Live on site
A2: In use | B2: Tribe REST | C2: High | D2: 1 | E2: Add now | F2: Not contacted | G2: Yes
A3: Check | B3: CivicPlus iCal | C3: Medium | D3: 2 | E3: Enable | F3: No reply | G3: No
A4: Disabled | B4: Plain iCal | C4: Low | D4: 3 | E4: Build connector | F4: Replied
A5: Candidate | B5: Squarespace JSON | D5: 4 | E5: Write selectors | F5: Feed received
A6: Declined | B6: HTML listing | E6: Email for feed address | F6: Declined
B7: WhoFi | E7: Ask for export
B8: LibCal | E8: Offer the form
B9: Event plugin API | E9: Confirm domain
B10: Eventbrite | E10: Retry probe
B11: Wix (ask) | E11: Keep as check
B12: Ticketing (ask) | E12: Declined
B13: Submission form | E13: Done
B14: Check source
B15: None
